log/output_50_2022_GRU_gpu5.log
wandb: W&B API key is configured. Use `wandb login --relogin` to force relogin
GPU device ID: 5
newdata/50_2022.npy
0
wandb: wandb version 0.17.9 is available!  To upgrade, please run:
wandb:  $ pip install wandb --upgrade
wandb: Tracking run with wandb version 0.12.17
wandb: Run data is saved locally in /home/qingyi/GPU20/DeepLOB/wandb/run-20240907_160535-2ou9mygc
wandb: Run `wandb offline` to turn off syncing.
wandb: Syncing run GRU
wandb: ⭐️ View project at https://wandb.ai/pqythu/futures50
wandb: 🚀 View run at https://wandb.ai/pqythu/futures50/runs/2ou9mygc
2024-09-07 16:05:46.549982: I tensorflow/core/platform/cpu_feature_guard.cc:193] This TensorFlow binary is optimized with oneAPI Deep Neural Network Library (oneDNN) to use the following CPU instructions in performance-critical operations:  AVX2 FMA
To enable them in other operations, rebuild TensorFlow with the appropriate compiler flags.
Model(
  (rnn): LSTM(10, 64, batch_first=True)
  (fc): Linear(in_features=64, out_features=5, bias=True)
)
number of parameters: 19781
Training start
epoch  1 | time used:  1.04s | train_loss 1.418 | valid loss 1.503 | valid acc 0.460 | mae 1.865 | mse 6.905 | rmse 2.63 | r2 -1.02 | sharp 1.99
epoch  2 | time used:  0.05s | train_loss 1.395 | valid loss 1.503 | valid acc 0.460 | mae 1.865 | mse 6.905 | rmse 2.63 | r2 -1.02 | sharp 1.99
epoch  3 | time used:  0.05s | train_loss 1.389 | valid loss 1.503 | valid acc 0.460 | mae 1.865 | mse 6.905 | rmse 2.63 | r2 -1.02 | sharp 1.99
epoch  4 | time used:  0.04s | train_loss 1.366 | valid loss 1.503 | valid acc 0.460 | mae 1.865 | mse 6.905 | rmse 2.63 | r2 -1.02 | sharp 1.99
epoch  5 | time used:  0.04s | train_loss 1.384 | valid loss 1.503 | valid acc 0.460 | mae 1.865 | mse 6.905 | rmse 2.63 | r2 -1.02 | sharp 1.99
epoch  6 | time used:  0.05s | train_loss 1.409 | valid loss 1.503 | valid acc 0.460 | mae 1.865 | mse 6.905 | rmse 2.63 | r2 -1.02 | sharp 1.99
epoch  7 | time used:  0.04s | train_loss 1.406 | valid loss 1.503 | valid acc 0.460 | mae 1.865 | mse 6.905 | rmse 2.63 | r2 -1.02 | sharp 1.99
epoch  8 | time used:  0.04s | train_loss 1.396 | valid loss 1.503 | valid acc 0.460 | mae 1.865 | mse 6.905 | rmse 2.63 | r2 -1.02 | sharp 1.99
epoch  9 | time used:  0.05s | train_loss 1.400 | valid loss 1.503 | valid acc 0.460 | mae 1.865 | mse 6.905 | rmse 2.63 | r2 -1.02 | sharp 1.99
epoch 10 | time used:  0.05s | train_loss 1.407 | valid loss 1.503 | valid acc 0.460 | mae 1.865 | mse 6.905 | rmse 2.63 | r2 -1.02 | sharp 1.99
saving the model to ./save/2022_50/GRU/checkpoint10.pt
epoch 11 | time used:  0.04s | train_loss 1.405 | valid loss 1.503 | valid acc 0.460 | mae 1.865 | mse 6.905 | rmse 2.63 | r2 -1.02 | sharp 1.99
epoch 12 | time used:  0.04s | train_loss 1.381 | valid loss 1.503 | valid acc 0.460 | mae 1.865 | mse 6.905 | rmse 2.63 | r2 -1.02 | sharp 1.99
epoch 13 | time used:  0.05s | train_loss 1.380 | valid loss 1.503 | valid acc 0.460 | mae 1.865 | mse 6.905 | rmse 2.63 | r2 -1.02 | sharp 1.99
epoch 14 | time used:  0.05s | train_loss 1.407 | valid loss 1.504 | valid acc 0.460 | mae 1.865 | mse 6.905 | rmse 2.63 | r2 -1.02 | sharp 1.99
epoch 15 | time used:  0.06s | train_loss 1.405 | valid loss 1.473 | valid acc 0.460 | mae 1.865 | mse 6.905 | rmse 2.63 | r2 -1.02 | sharp 1.99
epoch 16 | time used:  0.05s | train_loss 1.397 | valid loss 1.503 | valid acc 0.460 | mae 1.865 | mse 6.905 | rmse 2.63 | r2 -1.02 | sharp 1.99
epoch 17 | time used:  0.05s | train_loss 1.369 | valid loss 1.503 | valid acc 0.460 | mae 1.865 | mse 6.905 | rmse 2.63 | r2 -1.02 | sharp 1.99
epoch 18 | time used:  0.06s | train_loss 1.378 | valid loss 1.503 | valid acc 0.460 | mae 1.865 | mse 6.905 | rmse 2.63 | r2 -1.02 | sharp 1.99
epoch 19 | time used:  0.05s | train_loss 1.382 | valid loss 1.503 | valid acc 0.460 | mae 1.865 | mse 6.905 | rmse 2.63 | r2 -1.02 | sharp 1.99
epoch 20 | time used:  0.05s | train_loss 1.403 | valid loss 1.503 | valid acc 0.460 | mae 1.865 | mse 6.905 | rmse 2.63 | r2 -1.02 | sharp 1.99
saving the model to ./save/2022_50/GRU/checkpoint20.pt
epoch 21 | time used:  0.05s | train_loss 1.388 | valid loss 1.503 | valid acc 0.460 | mae 1.865 | mse 6.905 | rmse 2.63 | r2 -1.02 | sharp 1.99
epoch 22 | time used:  0.05s | train_loss 1.406 | valid loss 1.503 | valid acc 0.460 | mae 1.865 | mse 6.905 | rmse 2.63 | r2 -1.02 | sharp 1.99
epoch 23 | time used:  0.06s | train_loss 1.408 | valid loss 1.503 | valid acc 0.460 | mae 1.865 | mse 6.905 | rmse 2.63 | r2 -1.02 | sharp 1.99
epoch 24 | time used:  0.05s | train_loss 1.380 | valid loss 1.503 | valid acc 0.460 | mae 1.865 | mse 6.905 | rmse 2.63 | r2 -1.02 | sharp 1.99
epoch 25 | time used:  0.05s | train_loss 1.417 | valid loss 1.500 | valid acc 0.460 | mae 1.865 | mse 6.905 | rmse 2.63 | r2 -1.02 | sharp 1.99
epoch 26 | time used:  0.05s | train_loss 1.393 | valid loss 1.503 | valid acc 0.460 | mae 1.865 | mse 6.905 | rmse 2.63 | r2 -1.02 | sharp 1.99
epoch 27 | time used:  0.06s | train_loss 1.375 | valid loss 1.503 | valid acc 0.460 | mae 1.865 | mse 6.905 | rmse 2.63 | r2 -1.02 | sharp 1.99
epoch 28 | time used:  0.05s | train_loss 1.385 | valid loss 1.503 | valid acc 0.460 | mae 1.865 | mse 6.905 | rmse 2.63 | r2 -1.02 | sharp 1.99
epoch 29 | time used:  0.06s | train_loss 1.387 | valid loss 1.499 | valid acc 0.460 | mae 1.865 | mse 6.905 | rmse 2.63 | r2 -1.02 | sharp 1.99
epoch 30 | time used:  0.06s | train_loss 1.403 | valid loss 1.503 | valid acc 0.460 | mae 1.865 | mse 6.905 | rmse 2.63 | r2 -1.02 | sharp 1.99
saving the model to ./save/2022_50/GRU/checkpoint30.pt
epoch 31 | time used:  0.05s | train_loss 1.396 | valid loss 1.503 | valid acc 0.460 | mae 1.865 | mse 6.905 | rmse 2.63 | r2 -1.02 | sharp 1.99
epoch 32 | time used:  0.04s | train_loss 1.376 | valid loss 1.503 | valid acc 0.460 | mae 1.865 | mse 6.905 | rmse 2.63 | r2 -1.02 | sharp 1.99
epoch 33 | time used:  0.04s | train_loss 1.368 | valid loss 1.503 | valid acc 0.460 | mae 1.865 | mse 6.905 | rmse 2.63 | r2 -1.02 | sharp 1.99
epoch 34 | time used:  0.04s | train_loss 1.391 | valid loss 1.503 | valid acc 0.460 | mae 1.865 | mse 6.905 | rmse 2.63 | r2 -1.02 | sharp 1.99
epoch 35 | time used:  0.04s | train_loss 1.398 | valid loss 1.466 | valid acc 0.460 | mae 1.865 | mse 6.905 | rmse 2.63 | r2 -1.02 | sharp 1.99
epoch 36 | time used:  0.04s | train_loss 1.388 | valid loss 1.439 | valid acc 0.460 | mae 1.865 | mse 6.905 | rmse 2.63 | r2 -1.02 | sharp 1.99
epoch 37 | time used:  0.05s | train_loss 1.410 | valid loss 1.504 | valid acc 0.460 | mae 1.865 | mse 6.905 | rmse 2.63 | r2 -1.02 | sharp 1.99
epoch 38 | time used:  0.04s | train_loss 1.403 | valid loss 1.503 | valid acc 0.460 | mae 1.865 | mse 6.905 | rmse 2.63 | r2 -1.02 | sharp 1.99
epoch 39 | time used:  0.04s | train_loss 1.373 | valid loss 1.503 | valid acc 0.460 | mae 1.865 | mse 6.905 | rmse 2.63 | r2 -1.02 | sharp 1.99
epoch 40 | time used:  0.04s | train_loss 1.406 | valid loss 1.500 | valid acc 0.460 | mae 1.865 | mse 6.905 | rmse 2.63 | r2 -1.02 | sharp 1.99
saving the model to ./save/2022_50/GRU/checkpoint40.pt
epoch 41 | time used:  0.04s | train_loss 1.380 | valid loss 1.503 | valid acc 0.460 | mae 1.865 | mse 6.905 | rmse 2.63 | r2 -1.02 | sharp 1.99
epoch 42 | time used:  0.04s | train_loss 1.390 | valid loss 1.503 | valid acc 0.460 | mae 1.865 | mse 6.905 | rmse 2.63 | r2 -1.02 | sharp 1.99
epoch 43 | time used:  0.04s | train_loss 1.369 | valid loss 1.503 | valid acc 0.460 | mae 1.865 | mse 6.905 | rmse 2.63 | r2 -1.02 | sharp 1.99
epoch 44 | time used:  0.04s | train_loss 1.369 | valid loss 1.503 | valid acc 0.460 | mae 1.865 | mse 6.905 | rmse 2.63 | r2 -1.02 | sharp 1.99
epoch 45 | time used:  0.05s | train_loss 1.413 | valid loss 1.351 | valid acc 0.380 | mae 2.135 | mse 7.985 | rmse 2.83 | r2 -1.33 | sharp 0.00
epoch 46 | time used:  0.04s | train_loss 1.423 | valid loss 1.365 | valid acc 0.380 | mae 2.135 | mse 7.985 | rmse 2.83 | r2 -1.33 | sharp 0.00
