log/output_500_2020_Attention_gpu2.log
wandb: W&B API key is configured. Use `wandb login --relogin` to force relogin
GPU device ID: 2
newdata/500_2020.npy
2024-09-06 17:29:19.132142: I tensorflow/core/platform/cpu_feature_guard.cc:193] This TensorFlow binary is optimized with oneAPI Deep Neural Network Library (oneDNN) to use the following CPU instructions in performance-critical operations:  AVX2 FMA
To enable them in other operations, rebuild TensorFlow with the appropriate compiler flags.
2024-09-06 17:29:20.167629: W tensorflow/compiler/xla/stream_executor/platform/default/dso_loader.cc:64] Could not load dynamic library 'libnvinfer.so.7'; dlerror: libnvinfer.so.7: cannot open shared object file: No such file or directory; LD_LIBRARY_PATH: /opt/cudnn/lib64:/usr/local/cuda/lib64
2024-09-06 17:29:20.167749: W tensorflow/compiler/xla/stream_executor/platform/default/dso_loader.cc:64] Could not load dynamic library 'libnvinfer_plugin.so.7'; dlerror: libnvinfer_plugin.so.7: cannot open shared object file: No such file or directory; LD_LIBRARY_PATH: /opt/cudnn/lib64:/usr/local/cuda/lib64
2024-09-06 17:29:20.168120: W tensorflow/compiler/tf2tensorrt/utils/py_utils.cc:38] TF-TRT Warning: Cannot dlopen some TensorRT libraries. If you would like to use Nvidia GPU with TensorRT, please make sure the missing libraries mentioned above are installed properly.
wandb: wandb version 0.17.9 is available!  To upgrade, please run:
wandb:  $ pip install wandb --upgrade
wandb: Tracking run with wandb version 0.12.17
wandb: Run data is saved locally in /home/qingyi/GPU20/DeepLOB/wandb/run-20240906_172914-qyooqyt6
wandb: Run `wandb offline` to turn off syncing.
wandb: Syncing run Attention
wandb: ⭐️ View project at https://wandb.ai/pqythu/futures500
wandb: 🚀 View run at https://wandb.ai/pqythu/futures500/runs/qyooqyt6
Model(
  (attn): MultiheadAttention(
    (out_proj): NonDynamicallyQuantizableLinear(in_features=10, out_features=10, bias=True)
  )
  (fc): Linear(in_features=10, out_features=5, bias=True)
)
number of parameters: 495
Training start
epoch  1 | time used:  0.63s | train_loss 1.591 | valid loss 1.535 | valid acc 0.364 | mae 1.900 | mse 6.440 | rmse 2.54 | r2 -1.28 | sharp 0.00
epoch  2 | time used:  0.18s | train_loss 1.539 | valid loss 1.535 | valid acc 0.364 | mae 1.900 | mse 6.440 | rmse 2.54 | r2 -1.28 | sharp 0.00
epoch  3 | time used:  0.17s | train_loss 1.576 | valid loss 1.609 | valid acc 0.303 | mae 2.100 | mse 7.240 | rmse 2.69 | r2 -1.56 | sharp 1.77
epoch  4 | time used:  0.18s | train_loss 1.612 | valid loss 1.609 | valid acc 0.303 | mae 2.100 | mse 7.240 | rmse 2.69 | r2 -1.56 | sharp 1.77
epoch  5 | time used:  0.19s | train_loss 1.615 | valid loss 1.744 | valid acc 0.161 | mae 1.506 | mse 2.840 | rmse 1.69 | r2 -0.00 | sharp 1.77
epoch  6 | time used:  0.19s | train_loss 1.730 | valid loss 1.744 | valid acc 0.161 | mae 1.506 | mse 2.840 | rmse 1.69 | r2 -0.00 | sharp 1.77
epoch  7 | time used:  0.17s | train_loss 1.635 | valid loss 1.609 | valid acc 0.303 | mae 2.100 | mse 7.240 | rmse 2.69 | r2 -1.56 | sharp 1.77
epoch  8 | time used:  0.17s | train_loss 1.611 | valid loss 1.605 | valid acc 0.303 | mae 2.100 | mse 7.240 | rmse 2.69 | r2 -1.56 | sharp 1.77
epoch  9 | time used:  0.17s | train_loss 1.551 | valid loss 1.535 | valid acc 0.364 | mae 1.900 | mse 6.440 | rmse 2.54 | r2 -1.28 | sharp 0.00
epoch 10 | time used:  0.17s | train_loss 1.539 | valid loss 1.535 | valid acc 0.364 | mae 1.900 | mse 6.440 | rmse 2.54 | r2 -1.28 | sharp 0.00
saving the model to ./save/2020_500/Attention/checkpoint10.pt
epoch 11 | time used:  0.17s | train_loss 1.541 | valid loss 1.535 | valid acc 0.364 | mae 1.900 | mse 6.440 | rmse 2.54 | r2 -1.28 | sharp 0.00
epoch 12 | time used:  0.17s | train_loss 1.534 | valid loss 1.512 | valid acc 0.364 | mae 1.900 | mse 6.440 | rmse 2.54 | r2 -1.28 | sharp 0.00
epoch 13 | time used:  0.17s | train_loss 1.541 | valid loss 1.535 | valid acc 0.364 | mae 1.900 | mse 6.440 | rmse 2.54 | r2 -1.28 | sharp 0.00
epoch 14 | time used:  0.17s | train_loss 1.601 | valid loss 1.744 | valid acc 0.161 | mae 1.506 | mse 2.840 | rmse 1.69 | r2 -0.00 | sharp 1.77
epoch 15 | time used:  0.17s | train_loss 1.642 | valid loss 1.535 | valid acc 0.364 | mae 1.900 | mse 6.440 | rmse 2.54 | r2 -1.28 | sharp 0.00
epoch 16 | time used:  0.17s | train_loss 1.538 | valid loss 1.535 | valid acc 0.364 | mae 1.900 | mse 6.440 | rmse 2.54 | r2 -1.28 | sharp 0.00
epoch 17 | time used:  0.17s | train_loss 1.538 | valid loss 1.535 | valid acc 0.364 | mae 1.900 | mse 6.440 | rmse 2.54 | r2 -1.28 | sharp 0.00
epoch 18 | time used:  0.17s | train_loss 1.547 | valid loss 1.535 | valid acc 0.364 | mae 1.900 | mse 6.440 | rmse 2.54 | r2 -1.28 | sharp 0.00
epoch 19 | time used:  0.17s | train_loss 1.540 | valid loss 1.535 | valid acc 0.364 | mae 1.900 | mse 6.440 | rmse 2.54 | r2 -1.28 | sharp 0.00
epoch 20 | time used:  0.17s | train_loss 1.539 | valid loss 1.535 | valid acc 0.364 | mae 1.900 | mse 6.440 | rmse 2.54 | r2 -1.28 | sharp 0.00
saving the model to ./save/2020_500/Attention/checkpoint20.pt
epoch 21 | time used:  0.17s | train_loss 1.538 | valid loss 1.535 | valid acc 0.364 | mae 1.900 | mse 6.440 | rmse 2.54 | r2 -1.28 | sharp 0.00
epoch 22 | time used:  0.17s | train_loss 1.539 | valid loss 1.589 | valid acc 0.303 | mae 2.100 | mse 7.240 | rmse 2.69 | r2 -1.56 | sharp 1.77
epoch 23 | time used:  0.17s | train_loss 1.607 | valid loss 1.609 | valid acc 0.303 | mae 2.100 | mse 7.240 | rmse 2.69 | r2 -1.56 | sharp 1.77
epoch 24 | time used:  0.17s | train_loss 1.558 | valid loss 1.535 | valid acc 0.364 | mae 1.900 | mse 6.440 | rmse 2.54 | r2 -1.28 | sharp 0.00
epoch 25 | time used:  0.17s | train_loss 1.538 | valid loss 1.511 | valid acc 0.364 | mae 1.900 | mse 6.440 | rmse 2.54 | r2 -1.28 | sharp 0.00
epoch 26 | time used:  0.17s | train_loss 1.565 | valid loss 1.609 | valid acc 0.303 | mae 2.100 | mse 7.240 | rmse 2.69 | r2 -1.56 | sharp 1.77
epoch 27 | time used:  0.17s | train_loss 1.722 | valid loss 1.744 | valid acc 0.161 | mae 1.506 | mse 2.840 | rmse 1.69 | r2 -0.00 | sharp 1.77
epoch 28 | time used:  0.17s | train_loss 1.633 | valid loss 1.609 | valid acc 0.303 | mae 2.100 | mse 7.240 | rmse 2.69 | r2 -1.56 | sharp 1.77
epoch 29 | time used:  0.17s | train_loss 1.687 | valid loss 1.609 | valid acc 0.303 | mae 2.100 | mse 7.240 | rmse 2.69 | r2 -1.56 | sharp 1.77
epoch 30 | time used:  0.17s | train_loss 1.629 | valid loss 1.744 | valid acc 0.161 | mae 1.506 | mse 2.840 | rmse 1.69 | r2 -0.00 | sharp 1.77
saving the model to ./save/2020_500/Attention/checkpoint30.pt
epoch 31 | time used:  0.18s | train_loss 1.660 | valid loss 1.609 | valid acc 0.303 | mae 2.100 | mse 7.240 | rmse 2.69 | r2 -1.56 | sharp 1.77
epoch 32 | time used:  0.17s | train_loss 1.611 | valid loss 1.609 | valid acc 0.303 | mae 2.100 | mse 7.240 | rmse 2.69 | r2 -1.56 | sharp 1.77
epoch 33 | time used:  0.17s | train_loss 1.610 | valid loss 1.609 | valid acc 0.303 | mae 2.100 | mse 7.240 | rmse 2.69 | r2 -1.56 | sharp 1.77
epoch 34 | time used:  0.17s | train_loss 1.611 | valid loss 1.609 | valid acc 0.303 | mae 2.100 | mse 7.240 | rmse 2.69 | r2 -1.56 | sharp 1.77
epoch 35 | time used:  0.17s | train_loss 1.612 | valid loss 1.609 | valid acc 0.303 | mae 2.100 | mse 7.240 | rmse 2.69 | r2 -1.56 | sharp 1.77
epoch 36 | time used:  0.17s | train_loss 1.611 | valid loss 1.609 | valid acc 0.303 | mae 2.100 | mse 7.240 | rmse 2.69 | r2 -1.56 | sharp 1.77
epoch 37 | time used:  0.17s | train_loss 1.592 | valid loss 1.535 | valid acc 0.364 | mae 1.900 | mse 6.440 | rmse 2.54 | r2 -1.28 | sharp 0.00
epoch 38 | time used:  0.17s | train_loss 1.539 | valid loss 1.535 | valid acc 0.364 | mae 1.900 | mse 6.440 | rmse 2.54 | r2 -1.28 | sharp 0.00
epoch 39 | time used:  0.17s | train_loss 1.585 | valid loss 1.609 | valid acc 0.303 | mae 2.100 | mse 7.240 | rmse 2.69 | r2 -1.56 | sharp 1.77
epoch 40 | time used:  0.17s | train_loss 1.611 | valid loss 1.609 | valid acc 0.303 | mae 2.100 | mse 7.240 | rmse 2.69 | r2 -1.56 | sharp 1.77
